<?xml version='1.0'?>
<sdf version='1.4' xmlns:xacro="http://www.ros.org/wiki/xacro">

  <xacro:arg name="robot_id" default="X" />

  <xacro:macro name="shelfino" params="robot_id">


<!--
                                                      SHELFINO MODEL 
-->
  <model name="shelfino${robot_id}">

<!--
                                                      BODY OF SHELFINO 
-->
    <link name='base_link'>
      <inertial>
        <mass>20</mass>
        <inertia>
          <ixx>1.0</ixx><ixy>0.0</ixy><ixz>0.0</ixz><iyy>1.0</iyy><iyz>0.0</iyz><izz>1.0</izz>
        </inertia>
      </inertial>

      <visual name='body_visual'>
        <pose>0 0 0.25 0 0 0</pose>
        <geometry>
          <box>
            <size>0.5 0.5 0.4</size>
          </box>
        </geometry>
        <material>
          <diffuse>0.7 0.7 0.7 1</diffuse>
          <ambient>0.7 0.7 0.7 1</ambient>
        </material>
      </visual>

      <visual name='front_caster_visual'>
        <pose>-0.2 0 0.05 0 0 0</pose>
        <geometry>
          <sphere>
            <radius> 0.05 </radius>
          </sphere>
        </geometry>
      </visual>

      <visual name='back_caster_visual'>
        <pose>0.2 0 0.05 0 0 0</pose>
        <geometry>
          <sphere>
            <radius> 0.05 </radius>
          </sphere>
        </geometry>
      </visual>

      <collision name='collision'>
        <pose>0 0 0.225 0 0 0</pose>
        <geometry>
          <box>
            <size>0.5 0.5 0.45</size>
          </box>
        </geometry>
        <surface>
          <friction>
            <ode>
              <mu>0.0000001</mu>
              <mu2>0.0000001</mu2>
            </ode>
          </friction>
        </surface>
      </collision>
    </link>

<!--
                                                      LEFT WHEEL JOINT 
-->
    <joint name="wheel_left_joint" type="revolute">
      <parent>base_link</parent>
      <child>left_wheel</child>
      <pose>0 0 0 0 0 0</pose>
      <axis>
        <xyz>0 1 0</xyz>
      </axis>
    </joint>

<!--
                                                      LEFT WHEEL
-->
    <link name="left_wheel">
      <pose>0 0.27 0.125 0 1.5707 1.5707</pose>
      <visual name="visual">
        <geometry>
          <cylinder>
            <radius> 0.125 </radius>
            <length> 0.03 </length>
          </cylinder>
        </geometry>
        <material>
          <diffuse>0.1 0.1 0.1 1</diffuse>
          <ambient>0.1 0.1 0.1 1</ambient>
        </material>
      </visual>
      
      <collision name="collision">
        <geometry>
          <cylinder>
            <radius> 0.125 </radius>
            <length> 0.03 </length>
          </cylinder>
        </geometry>
        <surface>
          <friction>
            <ode>
              <mu>1000.0</mu>
              <mu2>1000.0</mu2>
              <slip1>0.0</slip1>
              <slip2>0.0</slip2>
            </ode>
          </friction>
        </surface>
      </collision>
    </link>    


<!--
                                                      RIGHT WHEEL JOINT 
-->
    <joint name="wheel_right_joint" type="revolute">
      <parent>base_link</parent>
      <child>right_wheel</child>
      <pose>0 0 0 0 0 0</pose>
      <axis>
        <xyz>0 1 0</xyz>
      </axis>
    </joint>

<!--
                                                      RIGHT WHEEL 
-->
    <link name="right_wheel">
      <pose>0 -0.27 0.125 0 1.5707 1.5707</pose>
      <visual name="visual">
        <geometry>
          <cylinder>
            <radius> 0.125 </radius>
            <length> 0.03 </length>
          </cylinder>
        </geometry>
        <material>
          <diffuse>0.1 0.1 0.1 1</diffuse>
          <ambient>0.1 0.1 0.1 1</ambient>
        </material>
      </visual>

      <collision name="collision">
        <geometry>
          <cylinder>
            <radius> 0.125 </radius>
            <length> 0.03 </length>
          </cylinder>
        </geometry>
        <surface>
          <friction>
            <ode>
              <mu>1000.0</mu>
              <mu2>1000.0</mu2>
              <slip1>0.0</slip1>
              <slip2>0.0</slip2>
            </ode>
          </friction>
        </surface>
      </collision>
    </link>

<!--
                                                      LIDAR FIXED JOINT 
-->
    <joint name="lidar2d_joint" type="fixed">
      <parent>base_link</parent>
      <child>lidar_link</child>
      <pose>0 0 0 0 0 0</pose>
    </joint>

<!--
                                                      LIDAR 
-->
    <link name="lidar_link">
      <pose>0 0 0.45 0 0 0</pose>
      <inertial>
        <mass>0.1</mass>
      </inertial>
      <!-- <visual name="visual">
        <geometry>
          <mesh>
            <uri>model://lidar2d/meshes/hokuyo.dae</uri>
          </mesh>
        </geometry>
      </visual> -->
      <collision name="collision-base">
        <pose>0 0 -0.0145 0 0 0</pose>
        <geometry>
          <box>
            <size>0.05 0.05 0.041</size>
          </box>
        </geometry>
      </collision>
      <collision name="collision-top">
        <pose>0 0 0.0205 0 0 0</pose>
        <geometry>
          <cylinder>
            <radius>0.021</radius>
            <length>0.029</length>
          </cylinder>
        </geometry>
      </collision>
      <sensor name="laser" type="ray">
        <always_on>true</always_on>
        <visualize>false</visualize>
        <update_rate>30</update_rate>
        <pose>0 0 0.03 0 0 0</pose>
        <ray>
          <scan>
            <horizontal>
              <samples>360</samples>
              <resolution>1</resolution>
              <min_angle>0</min_angle>
              <max_angle>6.28318530718</max_angle>
            </horizontal>
          </scan>
          <range>
            <min>0.15</min>
            <max>12.</max>
            <resolution>0.01</resolution>
          </range>
          <noise>
            <type>gaussian</type>
            <mean>0.0</mean>
            <stddev>0.02</stddev>
          </noise>
        </ray>
        <plugin name="laser" filename="libgazebo_ros_ray_sensor.so">
          <ros>
            <!-- Set namespace -->
            <!-- <namespace>${robot_id}</namespace> -->
            <remapping>~/out:=scan</remapping>
          </ros>
          <output_type>sensor_msgs/LaserScan</output_type>
          <frame_name>shelfino${robot_id}/base_laser</frame_name>
        </plugin>
      </sensor>
    </link>

<!--
                                                      DIFFERENTIAL DRIVE CONTROLLER 
-->
    <plugin name="differential_drive_controller" filename="libgazebo_ros_diff_drive.so">

      <!-- <ros> -->
        <!-- Set namespace -->
        <!-- <namespace>${robot_id}</namespace> -->
        <!-- <remapping>/tf:=tf</remapping> -->
      <!-- </ros> -->

      <!-- <alwaysOn>true</alwaysOn> -->

      <update_rate>30</update_rate>

      <!-- wheels -->
      <left_joint>wheel_left_joint</left_joint>
      <right_joint>wheel_right_joint</right_joint>

      <!-- kinematics -->
      <wheel_separation>0.54</wheel_separation>
      <wheel_diameter>0.25</wheel_diameter>

      <!-- limits -->
      <!-- <torque>20</torque> -->
      <max_wheel_torque>20</max_wheel_torque>
      <max_wheel_acceleration>1.0</max_wheel_acceleration>

      <command_topic>cmd_vel</command_topic>

      <!-- output -->
      <publish_odom>true</publish_odom>
      <publish_odom_tf>true</publish_odom_tf>
      <publish_wheel_tf>false</publish_wheel_tf>

      <odometry_frame>shelfino${robot_id}/odom</odometry_frame>
      <robot_base_frame>shelfino${robot_id}/base_link</robot_base_frame>

      <!-- <odometrySource>ENCODER</odometrySource> -->
      <!-- <odometrySource>WORLD</odometrySource> -->
    </plugin>

<!--
                                                      JOINT STATE PUBLISHER 
-->
    <plugin name="joint_state" filename="libgazebo_ros_joint_state_publisher.so">
      <ros>
        <remapping>~/out:=joint_states</remapping>
      </ros>
      <update_rate>30</update_rate>
      <joint_name>wheel_left_joint</joint_name>
      <joint_name>wheel_right_joint</joint_name>
    </plugin>   

  </model>

  </xacro:macro>

  <xacro:shelfino robot_id="$(arg robot_id)" />

</sdf>
